log_data = """
2023-06-04 09:40:21,175 [egwemimichae] [ERROR]  Error at downloading email - egwemimichael38@gmail.com - Traceback (most recent call last):
  File "socks.py", line 809, in connect
  File "socks.py", line 444, in _negotiate_SOCKS5
  File "socks.py", line 524, in _SOCKS5_request
  File "socks.py", line 276, in _readall
  File "socket.py", line 586, in readinto
socket.timeout: timed out

During handling of the above exception, another exception occurred:

Traceback (most recent call last):
  File "imap.py", line 315, in run
  File "proxy_imaplib.py", line 42, in __init__
  File "proxy_imaplib.py", line 71, in connect_proxy
  File "socks.py", line 47, in wrapper
  File "socks.py", line 814, in connect
socks.GeneralProxyError: Socket error: timed out

2023-06-04 09:40:21,179 [gabitreeente] [ERROR]  Error at downloading email - gabitreeenterprise@gmail.com - Traceback (most recent call last):
  File "socks.py", line 809, in connect
  File "socks.py", line 444, in _negotiate_SOCKS5
  File "socks.py", line 524, in _SOCKS5_request
  File "socks.py", line 276, in _readall
  File "socket.py", line 586, in readinto
socket.timeout: timed out

During handling of the above exception, another exception occurred:

Traceback (most recent call last):
  File "imap.py", line 315, in run
  File "proxy_imaplib.py", line 42, in __init__
  File "proxy_imaplib.py", line 71, in connect_proxy
  File "socks.py", line 47, in wrapper
  File "socks.py", line 814, in connect
socks.GeneralProxyError: Socket error: timed out

2023-03-26 22:41:15,717 [lydiaatuahen] [ERROR]  Error at downloading email - lydiaatuahene33@gmail.com - Traceback (most recent call last):
  File "imap.py", line 319, in run
  File "imaplib.py", line 598, in login
imaplib.IMAP4.error: b'[ALERT] Please log in via your web browser: https://support.google.com/mail/accounts/answer/78754 (Failure)'

2023-03-26 22:41:15,737 [aduforiregin] [ERROR]  Error at downloading email - aduforireginad@gmail.com - Traceback (most recent call last):
  File "imap.py", line 319, in run
  File "imaplib.py", line 598, in login
imaplib.IMAP4.error: b'[ALERT] Please log in via your web browser: https://support.google.com/mail/accounts/answer/78754 (Failure)'

2023-03-26 22:41:15,848 [matthew.soun] [ERROR]  Error at downloading email - matthew.soung@gmail.com - Traceback (most recent call last):
  File "imap.py", line 319, in run
  File "imaplib.py", line 598, in login
imaplib.IMAP4.error: b'[ALERT] Please log in via your web browser: https://support.google.com/mail/accounts/answer/78754 (Failure)'

2023-03-27 01:41:26,837 [abdullahidah] [ERROR]  Error at downloading email - abdullahidahiru029@gmail.com - Traceback (most recent call last):
  File "imap.py", line 319, in run
  File "imaplib.py", line 598, in login
imaplib.IMAP4.error: b'[AUTHENTICATIONFAILED] Invalid credentials (Failure)' 

2023-02-22 05:57:23,119 [chimeozoemen] [ERROR]  Error at downloading email - chimeozoemena@gmail.com - Traceback (most recent call last):
  File "imap.py", line 319, in run
  File "imaplib.py", line 596, in login
  File "imaplib.py", line 1196, in _simple_command
  File "imaplib.py", line 1019, in _command_complete
  File "imaplib.py", line 1139, in _get_tagged_response
  File "imaplib.py", line 1047, in _get_response
  File "imaplib.py", line 1149, in _get_line
  File "imaplib.py", line 310, in readline
  File "socket.py", line 586, in readinto
  File "ssl.py", line 1012, in recv_into
  File "ssl.py", line 874, in read
  File "ssl.py", line 631, in read
socket.timeout: The read operation timed out


2023-02-22 08:00:18,049 [Thread-1497 ] [INFO ]  
Starting Send Campaign : 
Target Removal - True
Group Selected: Group B
Webhook Enabled: False
Email Block Check: True
Emails Per Account: 25
Len of Group: 100
Len of Targets: 4999
Delay: 700 - 1500
Campaign ID: 3855fc2d-520f-4ad4-bd05-89f017c96726
Add Custom Hostname: False

2023-02-22 08:00:18,049 [Thread-1497 ] [INFO ]  
Starting Send Campaign : 
Target Removal - True
Group Selected: Group B
Webhook Enabled: False
Email Block Check: True
Emails Per Account: 25
Len of Group: 100
Len of Targets: 4999
Delay: 700 - 1500
Campaign ID: 3855fc2d-520f-4ad4-bd05-89f017c96726
Add Custom Hostname: False

2023-06-04 09:43:49,312 [shuaibumanma] [ERROR]  Error at Sending - shuaibumanmanzaria@gmail.com - Traceback (most recent call last):
  File "socks.py", line 809, in connect
  File "socks.py", line 444, in _negotiate_SOCKS5
  File "socks.py", line 524, in _SOCKS5_request
  File "socks.py", line 276, in _readall
  File "socket.py", line 586, in readinto
socket.timeout: timed out

During handling of the above exception, another exception occurred:

Traceback (most recent call last):
  File "smtp.py", line 376, in run
  File "smtp.py", line 312, in login
  File "proxy_smtplib.py", line 162, in connect_proxy
  File "socks.py", line 47, in wrapper
  File "socks.py", line 814, in connect
socks.GeneralProxyError: Socket error: timed out

2023-06-04 10:03:30,547 [abadaadamu@g] [INFO ]  Sent - abadaadamu@gmail.com steve@ispglass.com

2023-06-04 10:03:30,547 [abadaadamu@g] [INFO ]  Sent - abadaadamu@gmail.com steve@ispglass.com

2023-06-04 10:03:45,135 [MarkTargetAs] [ERROR]  Error at MarkTargetSentAirtable : Traceback (most recent call last):
  File "smtp.py", line 601, in run
  File "pyairtable\api\table.py", line 124, in batch_update
  File "pyairtable\api\abstract.py", line 189, in _batch_update
  File "pyairtable\api\abstract.py", line 95, in _request
  File "pyairtable\api\abstract.py", line 87, in _process_response
  File "pyairtable\api\abstract.py", line 74, in _process_response
  File "requests\models.py", line 953, in raise_for_status
requests.exceptions.HTTPError: ('422 Client Error: Unprocessable Entity for url: https://api.airtable.com/v0/appaCmKFn3MWDzjsF/Target%20GM-1', '422 Client Error: Unprocessable Entity for url: https://api.airtable.com/v0/appaCmKFn3MWDzjsF/Target%20GM-1 [Error: {\'type\': \'INVALID_VALUE_FOR_COLUMN\', \'message\': \'Field "Last Modified" cannot accept a value because the field is computed\'}]')

2023-06-04 10:03:45,135 [MarkTargetAs] [ERROR]  Error at MarkTargetSentAirtable : Traceback (most recent call last):
  File "smtp.py", line 601, in run
  File "pyairtable\api\table.py", line 124, in batch_update
  File "pyairtable\api\abstract.py", line 189, in _batch_update
  File "pyairtable\api\abstract.py", line 95, in _request
  File "pyairtable\api\abstract.py", line 87, in _process_response
  File "pyairtable\api\abstract.py", line 74, in _process_response
  File "requests\models.py", line 953, in raise_for_status
requests.exceptions.HTTPError: ('422 Client Error: Unprocessable Entity for url: https://api.airtable.com/v0/appaCmKFn3MWDzjsF/Target%20GM-1', '422 Client Error: Unprocessable Entity for url: https://api.airtable.com/v0/appaCmKFn3MWDzjsF/Target%20GM-1 [Error: {\'type\': \'INVALID_VALUE_FOR_COLUMN\', \'message\': \'Field "Last Modified" cannot accept a value because the field is computed\'}]')

2023-06-05 08:12:48,142 [obedabekamen] [ERROR]  Error at Sending - obedabekamensah2022@gmail.com - Traceback (most recent call last):
  File "smtp.py", line 376, in run
  File "smtp.py", line 320, in login
  File "smtplib.py", line 730, in login
  File "smtplib.py", line 721, in login
  File "smtplib.py", line 642, in auth
smtplib.SMTPAuthenticationError: (534, b'5.7.14 <https://accounts.google.com/signin/continue?sarp=1&scc=1&plt=AKgnsbt\n5.7.14 5RLnPQMrUmF0l77uz0IwU5934TAYagvqnFqD3uJ7xiFSC-OF2sAJ2e2gP6rHiT6Io7aCM\n5.7.14 fb_XUO5yrO7s6trN0UBkid-F6wCfW5G7yHN7tarAVDG6AzuhOSb_iqYbZYZvzjjC>\n5.7.14 Please log in via your web browser and then try again.\n5.7.14  Learn more at\n5.7.14  https://support.google.com/mail/answer/78754 c27-20020ac2531b000000b004f61a57797fsm833503lfh.60 - gsmtp')

"""